main function is running ...
       Model: FCN-16s (upsample with 5 step) 
 Learning rate: 0.001 
 Epoch number: 100 
 Batch size: 8 
 Weight name: ../weights/fcn16s_02_01.pkl 
 Log file: <_io.TextIOWrapper name='logs/fcn16s_02_01.txt' mode='w' encoding='UTF-8'> 
 =======================


 Epoch 0 | batch 0 | Training loss : 2.1719534397125244 

 Epoch 0 | batch 20 | Training loss : 1.9318618774414062 

 Epoch 0 | batch 40 | Training loss : 1.6693247556686401 

 Epoch 0 | batch 60 | Training loss : 1.795854926109314 

 Epoch 0 | batch 80 | Training loss : 1.6910290718078613 

 Epoch 0 | batch 100 | Training loss : 1.5740159749984741 

 Epoch 0 | batch 120 | Training loss : 1.389012336730957 

 Epoch 0 | batch 140 | Training loss : 1.3462692499160767 

Traceback (most recent call last):
  File "main.py", line 52, in <module>
    main()
  File "main.py", line 47, in main
    manager.train()
  File "/home/j1a0m0e4s/Semantic-Segmentation/model_manager.py", line 63, in train
    loss.backward()
  File "/usr/local/lib/python3.6/dist-packages/torch/tensor.py", line 93, in backward
    torch.autograd.backward(self, gradient, retain_graph, create_graph)
  File "/usr/local/lib/python3.6/dist-packages/torch/autograd/__init__.py", line 89, in backward
    allow_unreachable=True)  # allow_unreachable flag
KeyboardInterrupt
